[2023-09-18 18:47:58,612] INFO _log() L224   * Restarting with stat - call_trace=C:\Users\esous\AppData\Local\Programs\Python\Python311\Lib\site-packages\werkzeug\_internal.py L224 
[2023-09-18 18:48:03,144] INFO _log() L224  192.168.0.138 - - [18/Sep/2023 18:48:03] "GET /openapi/swagger HTTP/1.1" 200 - - call_trace=C:\Users\esous\AppData\Local\Programs\Python\Python311\Lib\site-packages\werkzeug\_internal.py L224 
[2023-09-18 18:48:03,236] INFO _log() L224  192.168.0.138 - - [18/Sep/2023 18:48:03] "[36mGET /openapi/static/css/swagger-ui.css HTTP/1.1[0m" 304 - - call_trace=C:\Users\esous\AppData\Local\Programs\Python\Python311\Lib\site-packages\werkzeug\_internal.py L224 
[2023-09-18 18:48:03,241] INFO _log() L224  192.168.0.138 - - [18/Sep/2023 18:48:03] "[36mGET /openapi/static/js/swagger-ui-bundle.js HTTP/1.1[0m" 304 - - call_trace=C:\Users\esous\AppData\Local\Programs\Python\Python311\Lib\site-packages\werkzeug\_internal.py L224 
[2023-09-18 18:48:03,243] INFO _log() L224  192.168.0.138 - - [18/Sep/2023 18:48:03] "[36mGET /openapi/static/js/swagger-ui-standalone-preset.js HTTP/1.1[0m" 304 - - call_trace=C:\Users\esous\AppData\Local\Programs\Python\Python311\Lib\site-packages\werkzeug\_internal.py L224 
[2023-09-18 18:48:03,415] INFO _log() L224  192.168.0.138 - - [18/Sep/2023 18:48:03] "GET /openapi/openapi.json HTTP/1.1" 200 - - call_trace=C:\Users\esous\AppData\Local\Programs\Python\Python311\Lib\site-packages\werkzeug\_internal.py L224 
[2023-09-18 18:48:03,415] INFO _log() L224  192.168.0.138 - - [18/Sep/2023 18:48:03] "[36mGET /openapi/static/images/swagger.svg HTTP/1.1[0m" 304 - - call_trace=C:\Users\esous\AppData\Local\Programs\Python\Python311\Lib\site-packages\werkzeug\_internal.py L224 
[2023-09-18 18:48:03,842] INFO _log() L224  192.168.0.138 - - [18/Sep/2023 18:48:03] "[33mGET /static/images/swagger.svg HTTP/1.1[0m" 404 - - call_trace=C:\Users\esous\AppData\Local\Programs\Python\Python311\Lib\site-packages\werkzeug\_internal.py L224 
[2023-09-18 18:48:03,963] INFO _log() L224  192.168.0.138 - - [18/Sep/2023 18:48:03] "[33mGET /static/images/swagger.svg HTTP/1.1[0m" 404 - - call_trace=C:\Users\esous\AppData\Local\Programs\Python\Python311\Lib\site-packages\werkzeug\_internal.py L224 
[2023-09-18 18:48:10,773] ERROR log_exception() L1449 Exception on /cep [GET] - call_trace=C:\Users\esous\AppData\Local\Programs\Python\Python311\Lib\site-packages\flask\app.py L1449
Traceback (most recent call last):
  File "C:\Users\esous\AppData\Local\Programs\Python\Python311\Lib\site-packages\flask\app.py", line 2073, in wsgi_app
    response = self.full_dispatch_request()
               ^^^^^^^^^^^^^^^^^^^^^^^^^^^^
  File "C:\Users\esous\AppData\Local\Programs\Python\Python311\Lib\site-packages\flask\app.py", line 1519, in full_dispatch_request
    rv = self.handle_user_exception(e)
         ^^^^^^^^^^^^^^^^^^^^^^^^^^^^^
  File "C:\Users\esous\AppData\Local\Programs\Python\Python311\Lib\site-packages\flask_cors\extension.py", line 165, in wrapped_function
    return cors_after_request(app.make_response(f(*args, **kwargs)))
                                                ^^^^^^^^^^^^^^^^^^
  File "C:\Users\esous\AppData\Local\Programs\Python\Python311\Lib\site-packages\flask\app.py", line 1517, in full_dispatch_request
    rv = self.dispatch_request()
         ^^^^^^^^^^^^^^^^^^^^^^^
  File "C:\Users\esous\AppData\Local\Programs\Python\Python311\Lib\site-packages\flask\app.py", line 1503, in dispatch_request
    return self.ensure_sync(self.view_functions[rule.endpoint])(**req.view_args)
           ^^^^^^^^^^^^^^^^^^^^^^^^^^^^^^^^^^^^^^^^^^^^^^^^^^^^^^^^^^^^^^^^^^^^^
  File "C:\Users\esous\AppData\Local\Programs\Python\Python311\Lib\site-packages\flask_openapi3\scaffold.py", line 104, in view_func
    response = func(**result)
               ^^^^^^^^^^^^^^
  File "C:\Treinamentos\GitHub\Puc-Rio\MVP\Sprint-III\component_c_prj_back\app.py", line 156, in get_cep
    cep = cep.replace("-", "").replace(".", "").replace(" ", "")
          ^^^
UnboundLocalError: cannot access local variable 'cep' where it is not associated with a value
[2023-09-18 18:48:10,780] INFO _log() L224  192.168.0.138 - - [18/Sep/2023 18:48:10] "[35m[1mGET /cep?cep=13193581 HTTP/1.1[0m" 500 - - call_trace=C:\Users\esous\AppData\Local\Programs\Python\Python311\Lib\site-packages\werkzeug\_internal.py L224 
[2023-09-18 18:48:19,219] ERROR log_exception() L1449 Exception on /cep [GET] - call_trace=C:\Users\esous\AppData\Local\Programs\Python\Python311\Lib\site-packages\flask\app.py L1449
Traceback (most recent call last):
  File "C:\Users\esous\AppData\Local\Programs\Python\Python311\Lib\site-packages\flask\app.py", line 2073, in wsgi_app
    response = self.full_dispatch_request()
               ^^^^^^^^^^^^^^^^^^^^^^^^^^^^
  File "C:\Users\esous\AppData\Local\Programs\Python\Python311\Lib\site-packages\flask\app.py", line 1519, in full_dispatch_request
    rv = self.handle_user_exception(e)
         ^^^^^^^^^^^^^^^^^^^^^^^^^^^^^
  File "C:\Users\esous\AppData\Local\Programs\Python\Python311\Lib\site-packages\flask_cors\extension.py", line 165, in wrapped_function
    return cors_after_request(app.make_response(f(*args, **kwargs)))
                                                ^^^^^^^^^^^^^^^^^^
  File "C:\Users\esous\AppData\Local\Programs\Python\Python311\Lib\site-packages\flask\app.py", line 1517, in full_dispatch_request
    rv = self.dispatch_request()
         ^^^^^^^^^^^^^^^^^^^^^^^
  File "C:\Users\esous\AppData\Local\Programs\Python\Python311\Lib\site-packages\flask\app.py", line 1503, in dispatch_request
    return self.ensure_sync(self.view_functions[rule.endpoint])(**req.view_args)
           ^^^^^^^^^^^^^^^^^^^^^^^^^^^^^^^^^^^^^^^^^^^^^^^^^^^^^^^^^^^^^^^^^^^^^
  File "C:\Users\esous\AppData\Local\Programs\Python\Python311\Lib\site-packages\flask_openapi3\scaffold.py", line 104, in view_func
    response = func(**result)
               ^^^^^^^^^^^^^^
  File "C:\Treinamentos\GitHub\Puc-Rio\MVP\Sprint-III\component_c_prj_back\app.py", line 156, in get_cep
    cep = cep.replace("-", "").replace(".", "").replace(" ", "")
          ^^^
UnboundLocalError: cannot access local variable 'cep' where it is not associated with a value
[2023-09-18 18:48:19,223] INFO _log() L224  192.168.0.138 - - [18/Sep/2023 18:48:19] "[35m[1mGET /cep?cep=25540260 HTTP/1.1[0m" 500 - - call_trace=C:\Users\esous\AppData\Local\Programs\Python\Python311\Lib\site-packages\werkzeug\_internal.py L224 
[2023-09-18 18:49:28,339] INFO _log() L224   * Detected change in 'C:\\Treinamentos\\GitHub\\Puc-Rio\\MVP\\Sprint-III\\component_c_prj_back\\app.py', reloading - call_trace=C:\Users\esous\AppData\Local\Programs\Python\Python311\Lib\site-packages\werkzeug\_internal.py L224 
[2023-09-18 18:49:28,468] INFO _log() L224   * Restarting with stat - call_trace=C:\Users\esous\AppData\Local\Programs\Python\Python311\Lib\site-packages\werkzeug\_internal.py L224 
[2023-09-18 18:49:28,853] INFO _log() L224   * Detected change in 'C:\\Treinamentos\\GitHub\\Puc-Rio\\MVP\\Sprint-III\\component_c_prj_back\\app.py', reloading - call_trace=C:\Users\esous\AppData\Local\Programs\Python\Python311\Lib\site-packages\werkzeug\_internal.py L224 
[2023-09-18 18:49:29,018] INFO _log() L224   * Restarting with stat - call_trace=C:\Users\esous\AppData\Local\Programs\Python\Python311\Lib\site-packages\werkzeug\_internal.py L224 
[2023-09-18 18:49:38,372] INFO _log() L224   * Running on all addresses (0.0.0.0)
   WARNING: This is a development server. Do not use it in a production deployment.
 * Running on http://127.0.0.1:5000
 * Running on http://192.168.0.138:5000 (Press CTRL+C to quit) - call_trace=C:\Users\esous\AppData\Local\Programs\Python\Python311\Lib\site-packages\werkzeug\_internal.py L224 
[2023-09-18 18:49:38,372] INFO _log() L224   * Restarting with stat - call_trace=C:\Users\esous\AppData\Local\Programs\Python\Python311\Lib\site-packages\werkzeug\_internal.py L224 
[2023-09-18 18:49:46,838] INFO _log() L224  192.168.0.138 - - [18/Sep/2023 18:49:46] "GET /openapi/swagger HTTP/1.1" 200 - - call_trace=C:\Users\esous\AppData\Local\Programs\Python\Python311\Lib\site-packages\werkzeug\_internal.py L224 
[2023-09-18 18:49:46,946] INFO _log() L224  192.168.0.138 - - [18/Sep/2023 18:49:46] "[36mGET /openapi/static/js/swagger-ui-bundle.js HTTP/1.1[0m" 304 - - call_trace=C:\Users\esous\AppData\Local\Programs\Python\Python311\Lib\site-packages\werkzeug\_internal.py L224 
[2023-09-18 18:49:46,946] INFO _log() L224  192.168.0.138 - - [18/Sep/2023 18:49:46] "[36mGET /openapi/static/css/swagger-ui.css HTTP/1.1[0m" 304 - - call_trace=C:\Users\esous\AppData\Local\Programs\Python\Python311\Lib\site-packages\werkzeug\_internal.py L224 
[2023-09-18 18:49:46,952] INFO _log() L224  192.168.0.138 - - [18/Sep/2023 18:49:46] "[36mGET /openapi/static/js/swagger-ui-standalone-preset.js HTTP/1.1[0m" 304 - - call_trace=C:\Users\esous\AppData\Local\Programs\Python\Python311\Lib\site-packages\werkzeug\_internal.py L224 
[2023-09-18 18:49:47,114] INFO _log() L224  192.168.0.138 - - [18/Sep/2023 18:49:47] "GET /openapi/openapi.json HTTP/1.1" 200 - - call_trace=C:\Users\esous\AppData\Local\Programs\Python\Python311\Lib\site-packages\werkzeug\_internal.py L224 
[2023-09-18 18:49:47,114] INFO _log() L224  192.168.0.138 - - [18/Sep/2023 18:49:47] "[36mGET /openapi/static/images/swagger.svg HTTP/1.1[0m" 304 - - call_trace=C:\Users\esous\AppData\Local\Programs\Python\Python311\Lib\site-packages\werkzeug\_internal.py L224 
[2023-09-18 18:49:47,593] INFO _log() L224  192.168.0.138 - - [18/Sep/2023 18:49:47] "[33mGET /static/images/swagger.svg HTTP/1.1[0m" 404 - - call_trace=C:\Users\esous\AppData\Local\Programs\Python\Python311\Lib\site-packages\werkzeug\_internal.py L224 
